FC defined as gfortran
CC defined as gcc
CXX defined as g++
SASS_ROOT: /home/erosita/sw/eSASSdevel
package SASS
package EROSITA
setup complete
using Simput File: /data17s/darksim/MD/MD_1.0Gpc/cat_AGN_SIMPUT/SIMPUT_000018_1024.fit 
determine the search cone ...
calculate the visibility GTIs ...
cleaning up ...
finished successfully!

ERROR: No such device or address
Task ero_vis 0.0 terminating with status 6
Unable to redirect prompts to the /dev/tty (at headas_stdio.c:152)
make event directory
compute gti with ero_vis
['ero_vis', 'GTIfile=/data01s/erosim/eRASS/sixte/018/erass_SIMPUT_000018_1024.gti', 'Simput=/data17s/darksim/MD/MD_1.0Gpc/cat_AGN_SIMPUT/SIMPUT_000018_1024.fit', 'Exposure=31536000.000000', 'Attitude=/data01s/erosim/eRASS/eRASS_Pc87M55_3dobi_att_remeis.fits', 'TSTART=0.000000', 'dt=10.0', 'visibility_range=1.0', 'clobber=yes']
Traceback (most recent call last):
  File "../simulate.py", line 176, in <module>
    Simulator(bkg, t_start, exposure, seed, simput_file_1, simput_file_2, simput_file_3, data_dir).run_all()
  File "../simulate.py", line 140, in run_all
    self.compute_gti(self._simput2)
  File "../simulate.py", line 97, in compute_gti
    subprocess.check_call(cmd)
  File "/home/comparat/miniconda3/envs/astroconda/lib/python3.7/subprocess.py", line 347, in check_call
    raise CalledProcessError(retcode, cmd)
subprocess.CalledProcessError: Command '['ero_vis', 'GTIfile=/data01s/erosim/eRASS/sixte/018/erass_SIMPUT_000018_512.gti', 'Simput=/data17s/darksim/MD/MD_1.0Gpc/cat_AGN_SIMPUT/SIMPUT_000018_512.fit', 'Exposure=31536000.000000', 'Attitude=/data01s/erosim/eRASS/eRASS_Pc87M55_3dobi_att_remeis.fits', 'TSTART=0.000000', 'dt=10.0', 'visibility_range=1.0', 'clobber=yes']' returned non-zero exit status 6.
ERROR: No such device or address
Task ero_calevents 0.0 terminating with status 6
Unable to redirect prompts to the /dev/tty (at headas_stdio.c:152)
['ero_calevents', 'Projection=AIT', 'Attitude=/data01s/erosim/eRASS/eRASS_Pc87M55_3dobi_att_remeis.fits', 'clobber=yes', 'EvtFile=/data01s/erosim/eRASS/sixte/018/erass_ccd1_evt.fits', 'eroEvtFile=/data01s/erosim/eRASS/sixte/018/cal_erass_ccd1_evt.fits', 'CCDNr=1', 'RA=1.5', 'Dec=0.0']
Traceback (most recent call last):
  File "../pre-process-esass.py", line 92, in <module>
    PrepareForEsass(ra_cen, dec_cen, data_dir).prep_and_merge()
  File "../pre-process-esass.py", line 81, in prep_and_merge
    self.cal_events()
  File "../pre-process-esass.py", line 41, in cal_events
    subprocess.check_call(cmd)
  File "/home/comparat/miniconda3/envs/astroconda/lib/python3.7/subprocess.py", line 347, in check_call
    raise CalledProcessError(retcode, cmd)
subprocess.CalledProcessError: Command '['ero_calevents', 'Projection=AIT', 'Attitude=/data01s/erosim/eRASS/eRASS_Pc87M55_3dobi_att_remeis.fits', 'clobber=yes', 'EvtFile=/data01s/erosim/eRASS/sixte/018/erass_ccd1_evt.fits', 'eroEvtFile=/data01s/erosim/eRASS/sixte/018/cal_erass_ccd1_evt.fits', 'CCDNr=1', 'RA=1.5', 'Dec=0.0']' returned non-zero exit status 6.
 evtool: v1.26/2.1 eSASSdevel 25. Jul 18:19:08 2019
 evtool/validate_tEvtool: **STOP** infile /data01s/erosim/eRASS/sixte/018/merged_erass.fits does not exist
 evtool: FAILED
['/data01s/erosim/eRASS/sixte/018/products/021_EventList_post.fits'] /data01s/erosim/eRASS/sixte/018/products/ 1 post
['evtool', 'eventfiles=/data01s/erosim/eRASS/sixte/018/merged_erass.fits', 'outfile=/data01s/erosim/eRASS/sixte/018/products/021_EventList_post.fits', 'emin=0.1', 'emax=0.5', 'image=yes', 'rebin=128', 'size=4096', 'pattern=15']
Traceback (most recent call last):
  File "../esass.py", line 324, in <module>
    esass_pipeline.run_pipeline()
  File "../esass.py", line 95, in run_pipeline
    subprocess.check_call(cmd)
  File "/home/comparat/miniconda3/envs/astroconda/lib/python3.7/subprocess.py", line 347, in check_call
    raise CalledProcessError(retcode, cmd)
subprocess.CalledProcessError: Command '['evtool', 'eventfiles=/data01s/erosim/eRASS/sixte/018/merged_erass.fits', 'outfile=/data01s/erosim/eRASS/sixte/018/products/021_EventList_post.fits', 'emin=0.1', 'emax=0.5', 'image=yes', 'rebin=128', 'size=4096', 'pattern=15']' returned non-zero exit status 1.
